<!-- Cheetah Model

    The state space is populated with joints in the order that they are
    defined in this file. The actuators also operate on joints.

    State-Space (name/joint/parameter):
        - rootx     slider      position (m)
        - rootz     slider      position (m)
        - rooty     hinge       angle (rad)
        - bthigh    hinge       angle (rad)
        - bshin     hinge       angle (rad)
        - bfoot     hinge       angle (rad)
        - fthigh    hinge       angle (rad)
        - fshin     hinge       angle (rad)
        - ffoot     hinge       angle (rad)
        - rootx     slider      velocity (m/s)
        - rootz     slider      velocity (m/s)
        - rooty     hinge       angular velocity (rad/s)
        - bthigh    hinge       angular velocity (rad/s)
        - bshin     hinge       angular velocity (rad/s)
        - bfoot     hinge       angular velocity (rad/s)
        - fthigh    hinge       angular velocity (rad/s)
        - fshin     hinge       angular velocity (rad/s)
        - ffoot     hinge       angular velocity (rad/s)

    Actuators (name/actuator/parameter):
        - bthigh    hinge       torque (N m)
        - bshin     hinge       torque (N m)
        - bfoot     hinge       torque (N m)
        - fthigh    hinge       torque (N m)
        - fshin     hinge       torque (N m)
        - ffoot     hinge       torque (N m)

-->
<mujoco model="cheetah">
  <compiler angle="radian" coordinate="local" inertiafromgeom="true" settotalmass="14"/>
  <default>
    <joint armature=".1" damping=".01" limited="true" solimplimit="0 .8 .03" solreflimit=".02 1" stiffness="8"/>
    <geom conaffinity="0" condim="3" contype="1" friction=".4 .1 .1" rgba="0.8 0.6 .4 1" solimp="0.0 0.8 0.01" solref="0.02 1"/>
    <motor ctrllimited="true" ctrlrange="-1 1"/>
  </default>
  <size nstack="300000" nuser_geom="1"/>
  <option gravity="0 0 -9.81" timestep="0.01"/>
  <asset>
    <texture builtin="gradient" height="100" rgb1="1 1 1" rgb2="0 0 0" type="skybox" width="100"/>
    <texture builtin="flat" height="1278" mark="cross" markrgb="1 1 1" name="texgeom" random="0.01" rgb1="0.8 0.6 0.4" rgb2="0.8 0.6 0.4" type="cube" width="127"/>
    <texture builtin="checker" height="100" name="texplane" rgb1="0 0 0" rgb2="0.8 0.8 0.8" type="2d" width="100"/>
    <material name="MatPlane" reflectance="0.5" shininess="1" specular="1" texrepeat="60 60" texture="texplane"/>
    <material name="geom" texture="texgeom" texuniform="true"/>
  </asset>
  <worldbody>
    <light cutoff="100" diffuse="1 1 1" dir="-0 0 -1.3" directional="true" exponent="1" pos="0 0 1.3" specular=".1 .1 .1"/>
    <geom conaffinity="1" condim="3" material="MatPlane" name="floor" pos="0 0 0" rgba="0.8 0.9 0.8 1" size="40 40 40" type="plane"/>
    <body name="torso" pos="0 0 .7">
      <joint armature="0" axis="1 0 0" damping="0" limited="false" name="rootx" pos="0 0 0" stiffness="0" type="slide"/>
      <joint armature="0" axis="0 0 1" damping="0" limited="false" name="rootz" pos="0 0 0" stiffness="0" type="slide"/>
      <joint armature="0" axis="0 1 0" damping="0" limited="false" name="rooty" pos="0 0 0" stiffness="0" type="hinge"/>
      <joint armature="0" axis="1 0 0" damping="0" limited="false" name="torsoroll" pos="0 0 0" stiffness="0" type="hinge"/>
      <geom fromto="-.5 0 0 .5 0 0" name="torso" size="0.075" type="capsule"/>
      <geom axisangle="0 1 0 .87" name="head" pos=".6 0 .1" size="0.075 .15" type="capsule"/>
      <body name="rbthigh" pos="-.5 0 0">
        <joint axis="0 1 0" damping="6" name="rbthigh" pos="0 -0.3 0" range="-.52 1.05" stiffness="240" type="hinge"/>
        <geom axisangle="0 1 0 -3.8" name="rbthigh" pos=".1 -0.3 -.13" size="0.046 .145" type="capsule"/>
        <body name="rbshin" pos=".16 0 -.25">
          <joint axis="0 1 0" damping="4.5" name="rbshin" pos="0 -0.3 0" range="-.785 .785" stiffness="180" type="hinge"/>
          <geom axisangle="0 1 0 -2.03" name="rbshin" pos="-.14 -0.3 -.07" rgba="0.9 0.6 0.6 1" size="0.046 .15" type="capsule"/>
          <body name="rbfoot" pos="-.28 0 -.14">
            <joint axis="0 1 0" damping="3" name="rbfoot" pos="0 -0.3 0" range="-.4 .785" stiffness="120" type="hinge"/>
            <geom axisangle="0 1 0 -.27" name="rbfoot" pos=".03 -0.3 -.097" rgba="0.9 0.6 0.6 1" size="0.046 .094" type="capsule"/>
          </body>
        </body>
      </body>
      <body name="lbthigh" pos="-.5 0 0">
        <joint axis="0 1 0" damping="6" name="lbthigh" pos="0 0.3 0" range="-.52 1.05" stiffness="240" type="hinge"/>
        <geom axisangle="0 1 0 -3.8" name="lbthigh" pos=".1 0.3 -.13" size="0.046 .145" type="capsule"/>
        <body name="lbshin" pos=".16 0 -.25">
          <joint axis="0 1 0" damping="4.5" name="lbshin" pos="0 0.3 0" range="-.785 .785" stiffness="180" type="hinge"/>
          <geom axisangle="0 1 0 -2.03" name="lbshin" pos="-.14 0.3 -.07" rgba="0.9 0.6 0.6 1" size="0.046 .15" type="capsule"/>
          <body name="lbfoot" pos="-.28 0 -.14">
            <joint axis="0 1 0" damping="3" name="lbfoot" pos="0 0.3 0" range="-.4 .785" stiffness="120" type="hinge"/>
            <geom axisangle="0 1 0 -.27" name="lbfoot" pos=".03 0.3 -.097" rgba="0.9 0.6 0.6 1" size="0.046 .094" type="capsule"/>
          </body>
        </body>
      </body>
      <body name="rfthigh" pos=".5 0 0">
        <joint axis="0 1 0" damping="4.5" name="rfthigh" pos="0 -0.2 0" range="-1 .7" stiffness="180" type="hinge"/>
        <geom axisangle="0 1 0 .52" name="rfthigh" pos="-.07 -0.2 -.12" size="0.046 .133" type="capsule"/>
        <body name="rfshin" pos="-.14 0 -.24">
          <joint axis="0 1 0" damping="3" name="rfshin" pos="0 -0.2 0" range="-1.2 .87" stiffness="120" type="hinge"/>
          <geom axisangle="0 1 0 -.6" name="rfshin" pos=".065 -0.2 -.09" rgba="0.9 0.6 0.6 1" size="0.046 .106" type="capsule"/>
          <body name="rffoot" pos=".13 0 -.18">
            <joint axis="0 1 0" damping="1.5" name="rffoot" pos="0 -0.2 0" range="-.5 .5" stiffness="60" type="hinge"/>
            <geom axisangle="0 1 0 -.6" name="rffoot" pos=".045 -0.2 -.07" rgba="0.9 0.6 0.6 1" size="0.046 .07" type="capsule"/>
          </body>
        </body>
      </body>
      <body name="lfthigh" pos=".5 0 0">
        <joint axis="0 1 0" damping="4.5" name="lfthigh" pos="0 0.2 0" range="-1 .7" stiffness="180" type="hinge"/>
        <geom axisangle="0 1 0 .52" name="lfthigh" pos="-.07 0.2 -.12" size="0.046 .133" type="capsule"/>
        <body name="lfshin" pos="-.14 0 -.24">
          <joint axis="0 1 0" damping="3" name="lfshin" pos="0 0.2 0" range="-1.2 .87" stiffness="120" type="hinge"/>
          <geom axisangle="0 1 0 -.6" name="lfshin" pos=".065 0.2 -.09" rgba="0.9 0.6 0.6 1" size="0.046 .106" type="capsule"/>
          <body name="lffoot" pos=".13 0 -.18">
            <joint axis="0 1 0" damping="1.5" name="lffoot" pos="0 0.2 0" range="-.5 .5" stiffness="60" type="hinge"/>
            <geom axisangle="0 1 0 -.6" name="lffoot" pos=".045 0.2 -.07" rgba="0.9 0.6 0.6 1" size="0.046 .07" type="capsule"/>
          </body>
        </body>
      </body>
    </body>
  </worldbody>
  <actuator>
    <motor gear="120" joint="rbthigh" name="rbthigh"/>
    <motor gear="90" joint="rbshin" name="rbshin"/>
    <motor gear="60" joint="rbfoot" name="rbfoot"/>
    <motor gear="120" joint="lbthigh" name="lbthigh"/>
    <motor gear="90" joint="lbshin" name="lbshin"/>
    <motor gear="60" joint="lbfoot" name="lbfoot"/>
    <motor gear="90" joint="rfthigh" name="fthigh"/>
    <motor gear="40" joint="rfshin" name="fshin"/>
    <motor gear="10" joint="rffoot" name="ffoot"/>
    <motor gear="90" joint="lfthigh" name="lfthigh"/>
    <motor gear="40" joint="lfshin" name="lfshin"/>
    <motor gear="10" joint="lffoot" name="lffoot"/>
  </actuator>
</mujoco>
