<!-- Metalhead Model V1

    The state space is populated with joints in the order that they are
    defined in this file. The actuators also operate on joints.

    State-Space (name/joint/parameter):
        - rootx     slider      position (m)
        - rootz     slider      position (m)
        - rooty     hinge       angle (rad)
        - bthigh    hinge       angle (rad)
        - bshin     hinge       angle (rad)
        - bfoot     hinge       angle (rad)
        - fthigh    hinge       angle (rad)
        - fshin     hinge       angle (rad)
        - ffoot     hinge       angle (rad)
        - rootx     slider      velocity (m/s)
        - rootz     slider      velocity (m/s)
        - rooty     hinge       angular velocity (rad/s)
        - bthigh    hinge       angular velocity (rad/s)
        - bshin     hinge       angular velocity (rad/s)
        - bfoot     hinge       angular velocity (rad/s)
        - fthigh    hinge       angular velocity (rad/s)
        - fshin     hinge       angular velocity (rad/s)
        - ffoot     hinge       angular velocity (rad/s)

    Actuators (name/actuator/parameter):
        - bthigh    hinge       torque (N m)
        - bshin     hinge       torque (N m)
        - bfoot     hinge       torque (N m)
        - fthigh    hinge       torque (N m)
        - fshin     hinge       torque (N m)
        - ffoot     hinge       torque (N m)

-->
<mujoco model="cheetah">
  <compiler angle="radian" coordinate="local" inertiafromgeom="true" settotalmass="14"/>
  <asset>
    <mesh name="body" file="stl/body_v1.stl" scale="0.001 0.001 0.001"/>
    <mesh name="back_left_thigh" file="stl/back_thigh_v1.stl" scale="0.001 0.001 0.001"/>
    <mesh name="back_right_thigh" file="stl/back_thigh_v1.stl" scale="0.001 -0.001 0.001"/>
    <mesh name="back_left_shin" file="stl/back_shin_v1.stl" scale="0.001 0.001 0.001"/>
    <mesh name="back_right_shin" file="stl/back_shin_v1.stl" scale="0.001 -0.001 0.001"/>
    <mesh name="back_left_foot" file="stl/back_foot_v1.stl" scale="0.001 0.001 0.001"/>
    <mesh name="back_right_foot" file="stl/back_foot_v1.stl" scale="0.001 -0.001 0.001"/>
    <mesh name="front_left_thigh" file="stl/front_thigh_v1.stl" scale="0.001 0.001 0.001"/>
    <mesh name="front_right_thigh" file="stl/front_thigh_v1.stl" scale="0.001 -0.001 0.001"/>
    <mesh name="front_left_shin" file="stl/front_shin_v1.stl" scale="0.001 0.001 0.001"/>
    <mesh name="front_right_shin" file="stl/front_shin_v1.stl" scale="0.001 -0.001 0.001"/>
    <mesh name="front_left_foot" file="stl/front_foot_v1.stl" scale="0.001 0.001 0.001"/>
    <mesh name="front_right_foot" file="stl/front_foot_v1.stl" scale="0.001 -0.001 0.001"/>
  </asset>
  <default>
    <joint armature=".1" damping=".01" limited="true" solimplimit="0 .8 .03" solreflimit=".02 1" stiffness="8"/>
    <geom conaffinity="0" condim="3" contype="1" friction=".4 .1 .1" rgba="0.8 0.6 .4 1" solimp="0.0 0.8 0.01" solref="0.02 1"/>
    <motor ctrllimited="true" ctrlrange="-1 1"/>
  </default>
  <size nstack="300000" nuser_geom="1"/>
  <option gravity="0 0 -9.81" timestep="0.01"/>
  <asset>
    <texture builtin="gradient" height="100" rgb1="1 1 1" rgb2="0 0 0" type="skybox" width="100"/>
    <texture builtin="flat" height="1278" mark="cross" markrgb="1 1 1" name="texgeom" random="0.01" rgb1="0.8 0.6 0.4" rgb2="0.8 0.6 0.4" type="cube" width="127"/>
    <texture builtin="checker" height="100" name="texplane" rgb1="0 0 0" rgb2="0.8 0.8 0.8" type="2d" width="100"/>
    <material name="MatPlane" reflectance="0.5" shininess="1" specular="1" texrepeat="60 60" texture="texplane"/>
    <material name="geom" texture="texgeom" texuniform="true"/>
  </asset>
  <worldbody>
    <light cutoff="100" diffuse="1 1 1" dir="-0 0 -1.3" directional="true" exponent="1" pos="0 0 1.3" specular=".1 .1 .1"/>
    <geom conaffinity="1" condim="3" material="MatPlane" name="floor" pos="0 0 0" rgba="0.8 0.9 0.8 1" size="40 40 40" type="plane"/>
    <body name="torso" pos="0 0 0.71">
      <joint armature="0" axis="1 0 0" damping="0" limited="false" name="rootx" pos="0 0 0" stiffness="0" type="slide"/>
      <joint armature="0" axis="0 0 1" damping="0" limited="false" name="rootz" pos="0 0 0" stiffness="0" type="slide"/>
      <joint armature="0" axis="0 1 0" damping="0" limited="false" name="torsopitch" pos="0 0 0" stiffness="0" type="hinge"/>
      <joint armature="0" axis="1 0 0" damping="0" limited="false" name="torsoroll" pos="0 0 0" stiffness="0" type="hinge"/>
      <!-- <geom fromto="-.5 0 0 .5 0 0" name="torso" size="0.075" type="capsule"/> -->
      <geom pos="-0.324 0 0" type="mesh" mesh="body" rgba="0.8 0.6 0.2 1"/>
      <!--- <body name="hip" pos="-.324 0 0">
        <geom name="hipmarker" pos="0 0 0" type="sphere" size="0.02" rgba="1.0 1.0 1.0 1"/>
      </body>
      <body name="backshinjoint" pos="-.28 0 -.266">
        <geom name="backshinjointmarker" pos="0 0 0" type="sphere" size="0.02" rgba="1.0 1.0 1.0 1"/>
      </body>
      <body name="backfootjoint" pos="-0.546 0 -0.318">
        <geom name="backfootjointmarker" pos="0 0 0" type="sphere" size="0.02" rgba="1.0 1.0 1.0 1"/>
      </body> -->
      <body name="back_left_thigh" pos="-.324 .11 0" axisangle="0 1 0 -0.1">
        <!-- <geom pos="0 -.025 0" type="sphere" size="0.02" rgba="1.0 1.0 1.0 1"/> -->
        <joint axis="0 1 0" damping="6" name="back_left_hip" range="-1.5 1.5" stiffness="80" type="hinge"/>
        <geom pos="0 0 0" type="mesh" mesh="back_left_thigh" rgba="0.2 0.8 0.2 1"/>
        <geom pos="0 .025 0" type="mesh" mesh="back_left_thigh" rgba="0.2 0.8 0.2 1"/>
        <body name="back_left_shin" pos="0 0 -.269" axisangle="0 1 0 0.9">
          <!-- <geom pos="0 -.025 0" type="sphere" size="0.02" rgba="1.0 1.0 1.0 1"/> -->
          <joint axis="0 1 0" damping="4.5" name="back_left_knee" pos="0 -0.3 0" range="-1.1 1.1" stiffness="60" type="hinge"/>
          <geom pos="0 0.005 0" type="mesh" mesh="back_left_shin" rgba="0.2 0.2 0.9 1"/>
          <geom pos="0 0.020 0" type="mesh" mesh="back_left_shin" rgba="0.2 0.2 0.9 1"/>
          <body name="back_left_foot" pos="0 0 -.271" axisangle="0 1 0 -0.9">
            <!-- <geom pos="0 -.025 0" type="sphere" size="0.02" rgba="1.0 1.0 1.0 1"/> -->
            <joint axis="0 1 0" damping="3" name="back_left_ankle" pos="0 -0.3 0" range="-.7 .7" stiffness="40" type="hinge"/>
            <geom pos="0 0 0"  type="mesh" mesh="back_left_foot" rgba="0.9 0.2 0.2 1" />
            <geom pos="0 0.025 0" type="mesh" mesh="back_left_foot" rgba="0.9 0.2 0.2 1" />
          </body>
        </body>
      </body>
      <body name="back_right_thigh" pos="-.324 -.11 0" axisangle="0 1 0 -0.1">
        <!-- <geom pos="0 -.025 0" type="sphere" size="0.02" rgba="1.0 1.0 1.0 1"/> -->
        <joint axis="0 1 0" damping="6" name="back_right_hip" range="-1.5 1.5" stiffness="80" type="hinge"/>
        <geom pos="0 0 0" type="mesh" mesh="back_right_thigh" rgba="0.2 0.8 0.2 1"/>
        <geom pos="0 -.025 0" type="mesh" mesh="back_right_thigh" rgba="0.2 0.8 0.2 1"/>
        <body name="back_right_shin" pos="0 0 -.269" axisangle="0 1 0 0.9">
          <!-- <geom pos="0 -.025 0" type="sphere" size="0.02" rgba="1.0 1.0 1.0 1"/> -->
          <joint axis="0 1 0" damping="4.5" name="back_right_knee" pos="0 -0.3 0" range="-1.1 1.1" stiffness="60" type="hinge"/>
          <geom pos="0 -0.005 0" type="mesh" mesh="back_right_shin" rgba="0.2 0.2 0.9 1"/>
          <geom pos="0 -0.020 0" type="mesh" mesh="back_right_shin" rgba="0.2 0.2 0.9 1"/>
          <body name="back_right_foot" pos="0 0 -.271" axisangle="0 1 0 -0.9">
            <!-- <geom pos="0 -.025 0" type="sphere" size="0.02" rgba="1.0 1.0 1.0 1"/> -->
            <joint axis="0 1 0" damping="3" name="back_right_ankle" pos="0 -0.3 0" range="-.7 .7" stiffness="40" type="hinge"/>
            <geom pos="0 0 0"  type="mesh" mesh="back_right_foot" rgba="0.9 0.2 0.2 1" />
            <geom pos="0 -0.025 0" type="mesh" mesh="back_right_foot" rgba="0.9 0.2 0.2 1" />
          </body>
        </body>
      </body>
      <body name="front_left_thigh" pos="0 .07 -.113" axisangle="0 1 0 0.16">
        <joint axis="0 1 0" damping="4.5" name="front_left_hip" range="-1.5 1.5" stiffness="60" type="hinge"/>
        <geom pos="0 0 0" type="mesh" mesh="front_left_thigh" rgba="0.2 0.8 0.2 1"/>
        <geom pos="0 .025 0" type="mesh" mesh="front_left_thigh" rgba="0.2 0.8 0.2 1"/>
        <body name="front_left_shin" pos="0 0 -.189" axisangle="0 1 0 -0.7">
          <joint axis="0 1 0" damping="3" name="front_left_knee" pos="0 -0.3 0" range="-1.1 1.1" stiffness="40" type="hinge"/>
          <geom pos="0 0.005 0" type="mesh" mesh="front_left_shin" rgba="0.2 0.2 0.9 1"/>
          <geom pos="0 0.020 0" type="mesh" mesh="front_left_shin" rgba="0.2 0.2 0.9 1"/>
          <body name="front_left_foot" pos="0 0 -.200" axisangle="0 1 0 0.5">
            <joint axis="0 1 0" damping="1.5" name="front_left_ankle" pos="0 -0.3 0" range="-.7 .7" stiffness="10" type="hinge"/>
            <geom pos="0 0 0" type="mesh" mesh="front_left_foot" rgba="0.9 0.2 0.2 1" />
            <geom pos="0 0.025 0" type="mesh" mesh="front_left_foot" rgba="0.9 0.2 0.2 1" />
          </body>
        </body>
      </body>
      <body name="front_right_thigh" pos="0 -.07 -.113" axisangle="0 1 0 0.16">
        <joint axis="0 1 0" damping="4.5" name="front_right_hip" range="-1.5 1.5" stiffness="60" type="hinge"/>
        <geom pos="0 0 0" type="mesh" mesh="front_right_thigh" rgba="0.2 0.8 0.2 1"/>
        <geom pos="0 -.025 0" type="mesh" mesh="front_right_thigh" rgba="0.2 0.8 0.2 1"/>
        <body name="front_right_shin" pos="0 0 -.189" axisangle="0 1 0 -0.7">
          <joint axis="0 1 0" damping="3" name="front_right_knee" pos="0 -0.3 0" range="-1.1 1.1" stiffness="40" type="hinge"/>
          <geom pos="0 -0.005 0" type="mesh" mesh="front_right_shin" rgba="0.2 0.2 0.9 1"/>
          <geom pos="0 -0.020 0" type="mesh" mesh="front_right_shin" rgba="0.2 0.2 0.9 1"/>
          <body name="front_right_foot" pos="0 0 -.200" axisangle="0 1 0 0.5">
            <joint axis="0 1 0" damping="1.5" name="front_right_ankle" pos="0 -0.3 0" range="-.7 .7" stiffness="10" type="hinge"/>
            <geom pos="0 0 0" type="mesh" mesh="front_right_foot" rgba="0.9 0.2 0.2 1" />
            <geom pos="0 -0.025 0" type="mesh" mesh="front_right_foot" rgba="0.9 0.2 0.2 1" />
          </body>
        </body>
      </body>
    </body>
  </worldbody>
  <actuator>
    <motor gear="30" joint="back_left_hip" name="back_left_hip"/>
    <motor gear="20" joint="back_left_knee" name="back_left_knee"/>
    <motor gear="10" joint="back_left_ankle" name="back_left_ankle"/>
    <motor gear="30" joint="back_right_hip" name="back_right_hip"/>
    <motor gear="20" joint="back_right_knee" name="back_right_knee"/>
    <motor gear="10" joint="back_right_ankle" name="back_right_ankle"/>
    <motor gear="30" joint="front_left_hip" name="front_left_hip"/>
    <motor gear="20" joint="front_left_knee" name="front_left_knee"/>
    <motor gear="10" joint="front_left_ankle" name="front_left_ankle"/>
    <motor gear="30" joint="front_right_hip" name="front_right_hip"/>
    <motor gear="20" joint="front_right_knee" name="front_right_knee"/>
    <motor gear="10" joint="front_right_ankle" name="front_right_ankle"/>
  </actuator>
</mujoco>
